---
title: 9-2 异常
top: 9.2
tags:
  - go
categories:
  - go
---

```go
package main

import "fmt"

/**
 * Go语言追求简洁优雅，不支持传统的try...catch...finally这种处理
 * Go中引入的处理方式为 defer panic recover
 * Go中可以抛出一个panic的异常，然后在defer中通过recover捕获这个异常，然后正常处理
 * recover 是内置函数，能够捕捉到一个函数里的第一个异常
 */
func divide(a int, b int) {
	defer func() {
		err := recover()
		if err != nil {
			fmt.Println("err:", err)
		}
	}()
	res := a / b
	fmt.Println("res=", res)
}
func main() {
	divide(10, 0)
	fmt.Println("计算结束")
}
```