---
title: 6 异常
top: 6
tags:
  - Java
categories:
  - Java
---

Exception 异常层次结构的根类 其是 Throwable 的子类 
ArithmeticException 算术错误异常
ArrayIndexOutOfBoundsException 数组下标越界异常 继承自IndexOutOfBoundsExceptio
NullPointerException 空指针异常 （指向为null时，却又调用成员方法）
ClassCastException 类型转换异常
NumberFormatException 数字格式不正确异常

<h4>异常捕获</h4>

```java
/*
Java 已经提供了异常处理机制，发生异常后，从最后一行开始，逐一往上可查找到错误原因
    其会提供异常原因、异常信息、异常位置
    缺点：出现异常后，后续语句不执行；提示信息太专业，可读性差
可以使用 try catch finally throw throws 来自定义
 */

public class Text {
    public static void main(String[] args) {
        //try 里出现异常，立即尝试 catch
        try {
            int i = 1;
            int o = 0;
            i = i / o;

            // Exception 异常层次结构的根类
            // 只要为当前异常的类或父类都能接住
        } catch (Exception e) {
            e.printStackTrace(); // 输出异常的堆栈信息
            System.err.println(e.toString()); //输出错误类型与提示信息  err 输出时为红色
            //输出自定义信息
            System.err.println("出错了");

            // throw e; //向上抛异常，但后面的语句不执行
        }

        //捕获成功后，未throw 则上述异常后，以下代码仍能执行
        System.err.println("byb");
    }
}
/*
Exception 异常层次结构的根类 其是 Throwable 的子类 
 */

```

<h4>finally</h4>

```java
public class Text {
    public static void main(String[] args) {
        try {
            int i = 1;
            int o = 0;
            i = i / o;
        } catch (Exception e) {

            //  finally 无论是否异常 是否异常捕获成功，是否 return 都会执行 finally里的语句
            // 如果执行了 System.exit(0); 退出虚拟机 自然 finally里的语句 就无法执行了
        } finally {
            System.err.println("byb1");
        }
        System.err.println("byb2");
    }
}

```

<h4>多重catch</h4>

```java
import java.util.InputMismatchException;

public class Text {
    public static void main(String[] args) {
        try {
            //多重 catch 异常
        } catch (InputMismatchException e) {


        }catch (ArithmeticException e) {

            //最后放个 Exception
        } catch (Exception e) {


        } finally {

        }

    }
}

```

```java
import java.util.InputMismatchException;

public class Text {
    public static void main(String[] args) {
        try {
            //多重 catch 异常
        } catch (InputMismatchException | ArithmeticException  e) {


        } catch (Exception e) {


        } finally {

        }

    }
}

```

<h4>运行时异常</h4>

```java
import java.util.Scanner;

/*
    要求：除数不能为0
 */
public class Text {
    public static void main(String[] args) {
        method();
    }

    public static void method() {
        Scanner input = new Scanner(System.in);
        System.out.println("请输入被除数");
        int num1 = input.nextInt();
        System.out.println("请输入除数");
        int num2 = input.nextInt();
        if (num2 == 0) {
            //运行时异常
            throw new RuntimeException("除数不能为0");
        }
    }
}


/*
Exception的其中一个子类 RuntimeException 为运行时异常
    RuntimeException 的子类包括 ArithmeticException  ArrayIndexOutOfBoundsException NullPointerException ...
 */
```

<h4>检查时异常</h4>

```java
import java.util.Scanner;

/*
    要求：除数不能为0
 */
public class Text {
    public static void main(String[] args) {
        try {
            method();
        } catch (Exception e) {
            e.printStackTrace();
        }
    }

    //throws 告诉方法的调用者,该方法可能会出现异常,让其来解决一下
    public static void method() throws Exception{
        Scanner input = new Scanner(System.in);
        System.out.println("请输入被除数");
        int num1 = input.nextInt();
        System.out.println("请输入除数");
        int num2 = input.nextInt();
        if (num2 == 0) {
            //检查时异常
            throw new Exception("除数不能为0");
        }
    }
}

```

```java
import java.util.Scanner;

/*
    要求：除数不能为0
 */
public class Text {
    //不想处理，继续 throws 向上抛 区别与 throw 
    //此处再往上 会造成 method() 方法的部分代码无法执行
    public static void main(String[] args) throws Exception {
        method();
    }

    //throws 告诉方法的调用者,该方法可能会出现异常,让其来解决一下
    public static void method() throws Exception{
        Scanner input = new Scanner(System.in);
        System.out.println("请输入被除数");
        int num1 = input.nextInt();
        System.out.println("请输入除数");
        int num2 = input.nextInt();
        if (num2 == 0) {
            //检查时异常
            throw new Exception("除数不能为0");
        }
    }
}

```

<h4>自定义异常</h4>

```java
//自定义检查时异常
class UserDefinedExceptions extends Exception {
    
    public UserDefinedExceptions() {
        super();
    }

    public UserDefinedExceptions(String message) {
        super(message);
    }
}
```

```java
//自定义运行时异常
class UserDefinedExceptions extends RuntimeException {

    public UserDefinedExceptions() {
        super();
    }

    public UserDefinedExceptions(String message) {
        super(message);
    }
}
```

<h4>异常链</h4>

暂无
